<sdf version='1.6'>
  <world name='default'>
    <light name='sun' type='directional'>
      <cast_shadows>1</cast_shadows>
      <pose frame=''>0 0 10 0 -0 0</pose>
      <diffuse>0.8 0.8 0.8 1</diffuse>
      <specular>0.2 0.2 0.2 1</specular>
      <attenuation>
        <range>1000</range>
        <constant>0.9</constant>
        <linear>0.01</linear>
        <quadratic>0.001</quadratic>
      </attenuation>
      <direction>-0.5 0.1 -0.9</direction>
    </light>
    <model name='ground_plane'>
      <static>1</static>
      <link name='link'>
        <collision name='collision'>
          <geometry>
            <plane>
              <normal>0 0 1</normal>
              <size>100 100</size>
            </plane>
          </geometry>
          <surface>
            <friction>
              <ode>
                <mu>100</mu>
                <mu2>50</mu2>
              </ode>
              <torsional>
                <ode/>
              </torsional>
            </friction>
            <contact>
              <ode/>
            </contact>
            <bounce/>
          </surface>
          <max_contacts>10</max_contacts>
        </collision>
        <visual name='visual'>
          <cast_shadows>0</cast_shadows>
          <geometry>
            <plane>
              <normal>0 0 1</normal>
              <size>100 100</size>
            </plane>
          </geometry>
          <material>
            <script>
              <uri>file://media/materials/scripts/gazebo.material</uri>
              <name>Gazebo/Grey</name>
            </script>
          </material>
        </visual>
        <self_collide>0</self_collide>
        <kinematic>0</kinematic>
      </link>
    </model>
    <gravity>0 0 -9.8</gravity>
    <magnetic_field>6e-06 2.3e-05 -4.2e-05</magnetic_field>
    <atmosphere type='adiabatic'/>
    <physics name='default_physics' default='0' type='ode'>
      <max_step_size>0.001</max_step_size>
      <real_time_factor>1</real_time_factor>
      <real_time_update_rate>1000</real_time_update_rate>
    </physics>
    <scene>
      <ambient>0.4 0.4 0.4 1</ambient>
      <background>0.7 0.7 0.7 1</background>
      <shadows>1</shadows>
    </scene>
    <spherical_coordinates>
      <surface_model>EARTH_WGS84</surface_model>
      <latitude_deg>0</latitude_deg>
      <longitude_deg>0</longitude_deg>
      <elevation>0</elevation>
      <heading_deg>0</heading_deg>
    </spherical_coordinates>
    <model name='thorvald_ii'>
      <link name='base_link'>
        <pose frame=''>0 0 0 0 -0 0</pose>
        <inertial>
          <pose frame=''>0 0 0.521429 0 -0 0</pose>
          <mass>84</mass>
          <inertia>
            <ixx>33.8454</ixx>
            <ixy>1.9984e-14</ixy>
            <ixz>-1.53143e-06</ixz>
            <iyy>30.5515</iyy>
            <iyz>-6.9952e-15</iyz>
            <izz>37.106</izz>
          </inertia>
        </inertial>
        <collision name='base_link_fixed_joint_lump__hokuyo_collision'>
          <pose frame=''>0.67 0 0.75 0 -0 0</pose>
          <geometry>
            <box>
              <size>0.1 0.1 0.1</size>
            </box>
          </geometry>
          <surface>
            <contact>
              <ode/>
            </contact>
            <friction>
              <ode/>
              <torsional>
                <ode/>
              </torsional>
            </friction>
            <bounce/>
          </surface>
          <max_contacts>10</max_contacts>
        </collision>
        <collision name='base_link_fixed_joint_lump__top0_collision_1'>
          <pose frame=''>-0.547 -0.3 0.65 0 -0 -3.14159</pose>
          <geometry>
            <mesh>
              <scale>1 1 1</scale>
              <uri>/home/vigneshnuc/Thorvald/src/Thorvald/thorvald_model/meshes/tower_modules/DUMMY-TOWER-M.stl</uri>
            </mesh>
          </geometry>
          <max_contacts>10</max_contacts>
          <surface>
            <contact>
              <ode/>
            </contact>
            <bounce/>
            <friction>
              <torsional>
                <ode/>
              </torsional>
              <ode/>
            </friction>
          </surface>
        </collision>
        <collision name='base_link_fixed_joint_lump__top1_collision_2'>
          <pose frame=''>0.547 -0.3 0.65 0 -0 0</pose>
          <geometry>
            <mesh>
              <scale>1 1 1</scale>
              <uri>/home/vigneshnuc/Thorvald/src/Thorvald/thorvald_model/meshes/tower_modules/DUMMY-TOWER-MIRROR-M.stl</uri>
            </mesh>
          </geometry>
          <max_contacts>10</max_contacts>
          <surface>
            <contact>
              <ode/>
            </contact>
            <bounce/>
            <friction>
              <torsional>
                <ode/>
              </torsional>
              <ode/>
            </friction>
          </surface>
        </collision>
        <collision name='base_link_fixed_joint_lump__top2_collision_3'>
          <pose frame=''>0.547 0.3 0.65 0 -0 0</pose>
          <geometry>
            <mesh>
              <scale>1 1 1</scale>
              <uri>/home/vigneshnuc/Thorvald/src/Thorvald/thorvald_model/meshes/tower_modules/DUMMY-TOWER-M.stl</uri>
            </mesh>
          </geometry>
          <max_contacts>10</max_contacts>
          <surface>
            <contact>
              <ode/>
            </contact>
            <bounce/>
            <friction>
              <torsional>
                <ode/>
              </torsional>
              <ode/>
            </friction>
          </surface>
        </collision>
        <collision name='base_link_fixed_joint_lump__top3_collision_4'>
          <pose frame=''>-0.547 0.3 0.65 0 -0 -3.14159</pose>
          <geometry>
            <mesh>
              <scale>1 1 1</scale>
              <uri>/home/vigneshnuc/Thorvald/src/Thorvald/thorvald_model/meshes/tower_modules/DUMMY-TOWER-MIRROR-M.stl</uri>
            </mesh>
          </geometry>
          <max_contacts>10</max_contacts>
          <surface>
            <contact>
              <ode/>
            </contact>
            <bounce/>
            <friction>
              <torsional>
                <ode/>
              </torsional>
              <ode/>
            </friction>
          </surface>
        </collision>
        <collision name='base_link_fixed_joint_lump__bat0_collision_5'>
          <pose frame=''>0 0.3 0.72 0 -0 -3.14159</pose>
          <geometry>
            <mesh>
              <scale>1 1 1</scale>
              <uri>/home/vigneshnuc/Thorvald/src/Thorvald/thorvald_model/meshes/bat_enc_modules/836586-1-DUMMY-RevA.stl</uri>
            </mesh>
          </geometry>
          <max_contacts>10</max_contacts>
          <surface>
            <contact>
              <ode/>
            </contact>
            <bounce/>
            <friction>
              <torsional>
                <ode/>
              </torsional>
              <ode/>
            </friction>
          </surface>
        </collision>
        <collision name='base_link_fixed_joint_lump__bat1_collision_6'>
          <pose frame=''>0 -0.3 0.72 0 -0 0</pose>
          <geometry>
            <mesh>
              <scale>1 1 1</scale>
              <uri>/home/vigneshnuc/Thorvald/src/Thorvald/thorvald_model/meshes/bat_enc_modules/836586-1-DUMMY-RevA.stl</uri>
            </mesh>
          </geometry>
          <max_contacts>10</max_contacts>
          <surface>
            <contact>
              <ode/>
            </contact>
            <bounce/>
            <friction>
              <torsional>
                <ode/>
              </torsional>
              <ode/>
            </friction>
          </surface>
        </collision>
        <collision name='base_link_fixed_joint_lump__pipe0_1_collision_7'>
          <pose frame=''>0 -0.3 0.575 1.5708 0 -1.5708</pose>
          <geometry>
            <cylinder>
              <length>0.85</length>
              <radius>0.02</radius>
            </cylinder>
          </geometry>
          <max_contacts>10</max_contacts>
          <surface>
            <contact>
              <ode/>
            </contact>
            <bounce/>
            <friction>
              <torsional>
                <ode/>
              </torsional>
              <ode/>
            </friction>
          </surface>
        </collision>
        <collision name='base_link_fixed_joint_lump__pipe0_2_collision_8'>
          <pose frame=''>0 -0.3 0.725 1.5708 0 -1.5708</pose>
          <geometry>
            <cylinder>
              <length>0.85</length>
              <radius>0.02</radius>
            </cylinder>
          </geometry>
          <max_contacts>10</max_contacts>
          <surface>
            <contact>
              <ode/>
            </contact>
            <bounce/>
            <friction>
              <torsional>
                <ode/>
              </torsional>
              <ode/>
            </friction>
          </surface>
        </collision>
        <collision name='base_link_fixed_joint_lump__pipe1_1_collision_9'>
          <pose frame=''>0.425 0 0.575 1.5708 -0 0</pose>
          <geometry>
            <cylinder>
              <length>0.6</length>
              <radius>0.02</radius>
            </cylinder>
          </geometry>
          <max_contacts>10</max_contacts>
          <surface>
            <contact>
              <ode/>
            </contact>
            <bounce/>
            <friction>
              <torsional>
                <ode/>
              </torsional>
              <ode/>
            </friction>
          </surface>
        </collision>
        <collision name='base_link_fixed_joint_lump__pipe1_2_collision_10'>
          <pose frame=''>0.425 0 0.725 1.5708 -0 0</pose>
          <geometry>
            <cylinder>
              <length>0.6</length>
              <radius>0.02</radius>
            </cylinder>
          </geometry>
          <max_contacts>10</max_contacts>
          <surface>
            <contact>
              <ode/>
            </contact>
            <bounce/>
            <friction>
              <torsional>
                <ode/>
              </torsional>
              <ode/>
            </friction>
          </surface>
        </collision>
        <collision name='base_link_fixed_joint_lump__pipe2_1_collision_11'>
          <pose frame=''>0 0.3 0.575 1.5708 -0 1.5708</pose>
          <geometry>
            <cylinder>
              <length>0.85</length>
              <radius>0.02</radius>
            </cylinder>
          </geometry>
          <max_contacts>10</max_contacts>
          <surface>
            <contact>
              <ode/>
            </contact>
            <bounce/>
            <friction>
              <torsional>
                <ode/>
              </torsional>
              <ode/>
            </friction>
          </surface>
        </collision>
        <collision name='base_link_fixed_joint_lump__pipe2_2_collision_12'>
          <pose frame=''>0 0.3 0.725 1.5708 -0 1.5708</pose>
          <geometry>
            <cylinder>
              <length>0.85</length>
              <radius>0.02</radius>
            </cylinder>
          </geometry>
          <max_contacts>10</max_contacts>
          <surface>
            <contact>
              <ode/>
            </contact>
            <bounce/>
            <friction>
              <torsional>
                <ode/>
              </torsional>
              <ode/>
            </friction>
          </surface>
        </collision>
        <collision name='base_link_fixed_joint_lump__pipe3_1_collision_13'>
          <pose frame=''>-0.425 0 0.575 1.5708 -0 3.14159</pose>
          <geometry>
            <cylinder>
              <length>0.6</length>
              <radius>0.02</radius>
            </cylinder>
          </geometry>
          <max_contacts>10</max_contacts>
          <surface>
            <contact>
              <ode/>
            </contact>
            <bounce/>
            <friction>
              <torsional>
                <ode/>
              </torsional>
              <ode/>
            </friction>
          </surface>
        </collision>
        <collision name='base_link_fixed_joint_lump__pipe3_2_collision_14'>
          <pose frame=''>-0.425 0 0.725 1.5708 -0 3.14159</pose>
          <geometry>
            <cylinder>
              <length>0.6</length>
              <radius>0.02</radius>
            </cylinder>
          </geometry>
          <max_contacts>10</max_contacts>
          <surface>
            <contact>
              <ode/>
            </contact>
            <bounce/>
            <friction>
              <torsional>
                <ode/>
              </torsional>
              <ode/>
            </friction>
          </surface>
        </collision>
        <visual name='base_link_fixed_joint_lump__hokuyo_visual'>
          <pose frame=''>0.67 0 0.75 0 -0 0</pose>
          <geometry>
            <mesh>
              <scale>1 1 1</scale>
              <uri>/home/vigneshnuc/Thorvald/src/Thorvald/thorvald_model/meshes/hokuyo/hokuyo.dae</uri>
            </mesh>
          </geometry>
          <material>
            <script>
              <uri>__default__</uri>
              <name>__default__</name>
            </script>
          </material>
        </visual>
        <visual name='base_link_fixed_joint_lump__top0_visual_1'>
          <pose frame=''>-0.547 -0.3 0.65 0 -0 -3.14159</pose>
          <geometry>
            <mesh>
              <scale>1 1 1</scale>
              <uri>/home/vigneshnuc/Thorvald/src/Thorvald/thorvald_model/meshes/tower_modules/DUMMY-TOWER-M.stl</uri>
            </mesh>
          </geometry>
        </visual>
        <visual name='base_link_fixed_joint_lump__top1_visual_2'>
          <pose frame=''>0.547 -0.3 0.65 0 -0 0</pose>
          <geometry>
            <mesh>
              <scale>1 1 1</scale>
              <uri>/home/vigneshnuc/Thorvald/src/Thorvald/thorvald_model/meshes/tower_modules/DUMMY-TOWER-MIRROR-M.stl</uri>
            </mesh>
          </geometry>
        </visual>
        <visual name='base_link_fixed_joint_lump__top2_visual_3'>
          <pose frame=''>0.547 0.3 0.65 0 -0 0</pose>
          <geometry>
            <mesh>
              <scale>1 1 1</scale>
              <uri>/home/vigneshnuc/Thorvald/src/Thorvald/thorvald_model/meshes/tower_modules/DUMMY-TOWER-M.stl</uri>
            </mesh>
          </geometry>
        </visual>
        <visual name='base_link_fixed_joint_lump__top3_visual_4'>
          <pose frame=''>-0.547 0.3 0.65 0 -0 -3.14159</pose>
          <geometry>
            <mesh>
              <scale>1 1 1</scale>
              <uri>/home/vigneshnuc/Thorvald/src/Thorvald/thorvald_model/meshes/tower_modules/DUMMY-TOWER-MIRROR-M.stl</uri>
            </mesh>
          </geometry>
        </visual>
        <visual name='base_link_fixed_joint_lump__bat0_visual_5'>
          <pose frame=''>0 0.3 0.72 0 -0 -3.14159</pose>
          <geometry>
            <mesh>
              <scale>1 1 1</scale>
              <uri>/home/vigneshnuc/Thorvald/src/Thorvald/thorvald_model/meshes/bat_enc_modules/836586-1-DUMMY-RevA.stl</uri>
            </mesh>
          </geometry>
        </visual>
        <visual name='base_link_fixed_joint_lump__bat1_visual_6'>
          <pose frame=''>0 -0.3 0.72 0 -0 0</pose>
          <geometry>
            <mesh>
              <scale>1 1 1</scale>
              <uri>/home/vigneshnuc/Thorvald/src/Thorvald/thorvald_model/meshes/bat_enc_modules/836586-1-DUMMY-RevA.stl</uri>
            </mesh>
          </geometry>
        </visual>
        <visual name='base_link_fixed_joint_lump__corner0_visual_7'>
          <pose frame=''>-0.368 -0.3 0.65 0 -0 3.14159</pose>
          <geometry>
            <cylinder>
              <length>0.15</length>
              <radius>0.02</radius>
            </cylinder>
          </geometry>
        </visual>
        <visual name='base_link_fixed_joint_lump__corner0_1_visual_8'>
          <pose frame=''>-0.425 -0.3 0.575 0 -0 3.14159</pose>
          <geometry>
            <mesh>
              <scale>1 1 1</scale>
              <uri>/home/vigneshnuc/Thorvald/src/Thorvald/thorvald_model/meshes/clamps/DUMMY-T-BRACKET.stl</uri>
            </mesh>
          </geometry>
        </visual>
        <visual name='base_link_fixed_joint_lump__corner0_2_visual_9'>
          <pose frame=''>-0.425 -0.3 0.725 0 -0 3.14159</pose>
          <geometry>
            <mesh>
              <scale>1 1 1</scale>
              <uri>/home/vigneshnuc/Thorvald/src/Thorvald/thorvald_model/meshes/clamps/DUMMY-T-BRACKET.stl</uri>
            </mesh>
          </geometry>
        </visual>
        <visual name='base_link_fixed_joint_lump__corner1_visual_10'>
          <pose frame=''>0.368 -0.3 0.65 0 -0 0</pose>
          <geometry>
            <cylinder>
              <length>0.15</length>
              <radius>0.02</radius>
            </cylinder>
          </geometry>
        </visual>
        <visual name='base_link_fixed_joint_lump__corner1_1_visual_11'>
          <pose frame=''>0.425 -0.3 0.575 0 -0 0</pose>
          <geometry>
            <mesh>
              <scale>1 1 1</scale>
              <uri>/home/vigneshnuc/Thorvald/src/Thorvald/thorvald_model/meshes/clamps/DUMMY-T-BRACKET.stl</uri>
            </mesh>
          </geometry>
        </visual>
        <visual name='base_link_fixed_joint_lump__corner1_2_visual_12'>
          <pose frame=''>0.425 -0.3 0.725 0 -0 0</pose>
          <geometry>
            <mesh>
              <scale>1 1 1</scale>
              <uri>/home/vigneshnuc/Thorvald/src/Thorvald/thorvald_model/meshes/clamps/DUMMY-T-BRACKET.stl</uri>
            </mesh>
          </geometry>
        </visual>
        <visual name='base_link_fixed_joint_lump__corner2_visual_13'>
          <pose frame=''>0.368 0.3 0.65 0 -0 0</pose>
          <geometry>
            <cylinder>
              <length>0.15</length>
              <radius>0.02</radius>
            </cylinder>
          </geometry>
        </visual>
        <visual name='base_link_fixed_joint_lump__corner2_1_visual_14'>
          <pose frame=''>0.425 0.3 0.575 0 -0 0</pose>
          <geometry>
            <mesh>
              <scale>1 1 1</scale>
              <uri>/home/vigneshnuc/Thorvald/src/Thorvald/thorvald_model/meshes/clamps/DUMMY-T-BRACKET.stl</uri>
            </mesh>
          </geometry>
        </visual>
        <visual name='base_link_fixed_joint_lump__corner2_2_visual_15'>
          <pose frame=''>0.425 0.3 0.725 0 -0 0</pose>
          <geometry>
            <mesh>
              <scale>1 1 1</scale>
              <uri>/home/vigneshnuc/Thorvald/src/Thorvald/thorvald_model/meshes/clamps/DUMMY-T-BRACKET.stl</uri>
            </mesh>
          </geometry>
        </visual>
        <visual name='base_link_fixed_joint_lump__corner3_visual_16'>
          <pose frame=''>-0.368 0.3 0.65 0 -0 3.14159</pose>
          <geometry>
            <cylinder>
              <length>0.15</length>
              <radius>0.02</radius>
            </cylinder>
          </geometry>
        </visual>
        <visual name='base_link_fixed_joint_lump__corner3_1_visual_17'>
          <pose frame=''>-0.425 0.3 0.575 0 -0 3.14159</pose>
          <geometry>
            <mesh>
              <scale>1 1 1</scale>
              <uri>/home/vigneshnuc/Thorvald/src/Thorvald/thorvald_model/meshes/clamps/DUMMY-T-BRACKET.stl</uri>
            </mesh>
          </geometry>
        </visual>
        <visual name='base_link_fixed_joint_lump__corner3_2_visual_18'>
          <pose frame=''>-0.425 0.3 0.725 0 -0 3.14159</pose>
          <geometry>
            <mesh>
              <scale>1 1 1</scale>
              <uri>/home/vigneshnuc/Thorvald/src/Thorvald/thorvald_model/meshes/clamps/DUMMY-T-BRACKET.stl</uri>
            </mesh>
          </geometry>
        </visual>
        <visual name='base_link_fixed_joint_lump__pipe0_1_visual_19'>
          <pose frame=''>0 -0.3 0.575 1.5708 0 -1.5708</pose>
          <geometry>
            <cylinder>
              <length>0.85</length>
              <radius>0.02</radius>
            </cylinder>
          </geometry>
        </visual>
        <visual name='base_link_fixed_joint_lump__pipe0_2_visual_20'>
          <pose frame=''>0 -0.3 0.725 1.5708 0 -1.5708</pose>
          <geometry>
            <cylinder>
              <length>0.85</length>
              <radius>0.02</radius>
            </cylinder>
          </geometry>
        </visual>
        <visual name='base_link_fixed_joint_lump__pipe1_1_visual_21'>
          <pose frame=''>0.425 0 0.575 1.5708 -0 0</pose>
          <geometry>
            <cylinder>
              <length>0.6</length>
              <radius>0.02</radius>
            </cylinder>
          </geometry>
        </visual>
        <visual name='base_link_fixed_joint_lump__pipe1_2_visual_22'>
          <pose frame=''>0.425 0 0.725 1.5708 -0 0</pose>
          <geometry>
            <cylinder>
              <length>0.6</length>
              <radius>0.02</radius>
            </cylinder>
          </geometry>
        </visual>
        <visual name='base_link_fixed_joint_lump__pipe2_1_visual_23'>
          <pose frame=''>0 0.3 0.575 1.5708 -0 1.5708</pose>
          <geometry>
            <cylinder>
              <length>0.85</length>
              <radius>0.02</radius>
            </cylinder>
          </geometry>
        </visual>
        <visual name='base_link_fixed_joint_lump__pipe2_2_visual_24'>
          <pose frame=''>0 0.3 0.725 1.5708 -0 1.5708</pose>
          <geometry>
            <cylinder>
              <length>0.85</length>
              <radius>0.02</radius>
            </cylinder>
          </geometry>
        </visual>
        <visual name='base_link_fixed_joint_lump__pipe3_1_visual_25'>
          <pose frame=''>-0.425 0 0.575 1.5708 -0 3.14159</pose>
          <geometry>
            <cylinder>
              <length>0.6</length>
              <radius>0.02</radius>
            </cylinder>
          </geometry>
        </visual>
        <visual name='base_link_fixed_joint_lump__pipe3_2_visual_26'>
          <pose frame=''>-0.425 0 0.725 1.5708 -0 3.14159</pose>
          <geometry>
            <cylinder>
              <length>0.6</length>
              <radius>0.02</radius>
            </cylinder>
          </geometry>
        </visual>
        <gravity>1</gravity>
        <velocity_decay/>
        <sensor name='head_hokuyo_sensor' type='ray'>
          <visualize>1</visualize>
          <update_rate>40</update_rate>
          <always_on>1</always_on>
          <ray>
            <scan>
              <horizontal>
                <samples>1080</samples>
                <resolution>1</resolution>
                <min_angle>-1.5708</min_angle>
                <max_angle>1.5708</max_angle>
              </horizontal>
              <vertical>
                <samples>1</samples>
                <min_angle>0</min_angle>
                <max_angle>0</max_angle>
              </vertical>
            </scan>
            <range>
              <min>0.1</min>
              <max>30</max>
              <resolution>0.01</resolution>
            </range>
            <noise>
              <type>gaussian</type>
              <mean>0</mean>
              <stddev>0.01</stddev>
            </noise>
          </ray>
          <plugin name='hokuyo_node' filename='libgazebo_ros_laser.so'>
            <topicName>scan</topicName>
            <frameName>hokuyo</frameName>
            <robotNamespace>/</robotNamespace>
          </plugin>
          <pose frame=''>0.67 0 0.75 0 -0 0</pose>
        </sensor>
        <self_collide>0</self_collide>
        <kinematic>0</kinematic>
      </link>
      <link name='leg0'>
        <pose frame=''>-0.547 -0.3 0.2 0 -0 0</pose>
        <inertial>
          <pose frame=''>0 0 0 0 -0 0</pose>
          <mass>1</mass>
          <inertia>
            <ixx>1</ixx>
            <ixy>0</ixy>
            <ixz>0</ixz>
            <iyy>1</iyy>
            <iyz>0</iyz>
            <izz>1</izz>
          </inertia>
        </inertial>
        <collision name='leg0_collision'>
          <pose frame=''>0 0 0 0 -0 -3.14159</pose>
          <geometry>
            <mesh>
              <scale>1 1 1</scale>
              <uri>/home/vigneshnuc/Thorvald/src/Thorvald/thorvald_model/meshes/drive_modules/836745-5-DUMMY-RevA.stl</uri>
            </mesh>
          </geometry>
          <max_contacts>10</max_contacts>
          <surface>
            <contact>
              <ode/>
            </contact>
            <bounce/>
            <friction>
              <torsional>
                <ode/>
              </torsional>
              <ode/>
            </friction>
          </surface>
        </collision>
        <visual name='leg0_visual'>
          <pose frame=''>0 0 0 0 -0 -3.14159</pose>
          <geometry>
            <mesh>
              <scale>1 1 1</scale>
              <uri>/home/vigneshnuc/Thorvald/src/Thorvald/thorvald_model/meshes/drive_modules/836745-5-DUMMY-RevA.stl</uri>
            </mesh>
          </geometry>
        </visual>
        <self_collide>0</self_collide>
        <kinematic>0</kinematic>
      </link>
      <joint name='steering0' type='revolute'>
        <child>leg0</child>
        <parent>base_link</parent>
        <axis>
          <xyz>0 0 1</xyz>
          <limit>
            <lower>-1e+16</lower>
            <upper>1e+16</upper>
          </limit>
          <dynamics>
            <spring_reference>0</spring_reference>
            <spring_stiffness>0</spring_stiffness>
          </dynamics>
          <use_parent_model_frame>1</use_parent_model_frame>
        </axis>
      </joint>
      <link name='wheel0_link'>
        <pose frame=''>-0.547 -0.3 0.2 -1.5708 0 0</pose>
        <inertial>
          <pose frame=''>0 0 0 0 -0 0</pose>
          <mass>1</mass>
          <inertia>
            <ixx>1</ixx>
            <ixy>0</ixy>
            <ixz>0</ixz>
            <iyy>1</iyy>
            <iyz>0</iyz>
            <izz>1</izz>
          </inertia>
        </inertial>
        <collision name='wheel0_link_collision'>
          <pose frame=''>0 0 0 0 -0 0</pose>
          <geometry>
            <cylinder>
              <length>0.16</length>
              <radius>0.2</radius>
            </cylinder>
          </geometry>
          <surface>
            <contact>
              <ode/>
            </contact>
            <friction>
              <ode/>
              <torsional>
                <ode/>
              </torsional>
            </friction>
            <bounce/>
          </surface>
          <max_contacts>10</max_contacts>
        </collision>
        <visual name='wheel0_link_visual'>
          <pose frame=''>0 0 0 0 -0 0</pose>
          <geometry>
            <cylinder>
              <length>0.16</length>
              <radius>0.2</radius>
            </cylinder>
          </geometry>
          <material>
            <script>
              <name>Gazebo/Black</name>
              <uri>file://media/materials/scripts/gazebo.material</uri>
            </script>
          </material>
        </visual>
        <gravity>1</gravity>
        <velocity_decay/>
        <self_collide>0</self_collide>
        <kinematic>0</kinematic>
      </link>
      <joint name='wheel0' type='revolute'>
        <child>wheel0_link</child>
        <parent>leg0</parent>
        <axis>
          <xyz>0 1 0</xyz>
          <limit>
            <lower>-1e+16</lower>
            <upper>1e+16</upper>
          </limit>
          <dynamics>
            <spring_reference>0</spring_reference>
            <spring_stiffness>0</spring_stiffness>
          </dynamics>
          <use_parent_model_frame>1</use_parent_model_frame>
        </axis>
      </joint>
      <link name='leg1'>
        <pose frame=''>0.547 -0.3 0.2 0 -0 0</pose>
        <inertial>
          <pose frame=''>0 0 0 0 -0 0</pose>
          <mass>1</mass>
          <inertia>
            <ixx>1</ixx>
            <ixy>0</ixy>
            <ixz>0</ixz>
            <iyy>1</iyy>
            <iyz>0</iyz>
            <izz>1</izz>
          </inertia>
        </inertial>
        <collision name='leg1_collision'>
          <pose frame=''>0 0 0 0 -0 0</pose>
          <geometry>
            <mesh>
              <scale>1 1 1</scale>
              <uri>/home/vigneshnuc/Thorvald/src/Thorvald/thorvald_model/meshes/drive_modules/836745-5-DUMMY-MIRROR-RevA.stl</uri>
            </mesh>
          </geometry>
          <max_contacts>10</max_contacts>
          <surface>
            <contact>
              <ode/>
            </contact>
            <bounce/>
            <friction>
              <torsional>
                <ode/>
              </torsional>
              <ode/>
            </friction>
          </surface>
        </collision>
        <visual name='leg1_visual'>
          <pose frame=''>0 0 0 0 -0 0</pose>
          <geometry>
            <mesh>
              <scale>1 1 1</scale>
              <uri>/home/vigneshnuc/Thorvald/src/Thorvald/thorvald_model/meshes/drive_modules/836745-5-DUMMY-MIRROR-RevA.stl</uri>
            </mesh>
          </geometry>
        </visual>
        <self_collide>0</self_collide>
        <kinematic>0</kinematic>
      </link>
      <joint name='steering1' type='revolute'>
        <child>leg1</child>
        <parent>base_link</parent>
        <axis>
          <xyz>0 0 1</xyz>
          <limit>
            <lower>-1e+16</lower>
            <upper>1e+16</upper>
          </limit>
          <dynamics>
            <spring_reference>0</spring_reference>
            <spring_stiffness>0</spring_stiffness>
          </dynamics>
          <use_parent_model_frame>1</use_parent_model_frame>
        </axis>
      </joint>
      <link name='wheel1_link'>
        <pose frame=''>0.547 -0.3 0.2 -1.5708 0 0</pose>
        <inertial>
          <pose frame=''>0 0 0 0 -0 0</pose>
          <mass>1</mass>
          <inertia>
            <ixx>1</ixx>
            <ixy>0</ixy>
            <ixz>0</ixz>
            <iyy>1</iyy>
            <iyz>0</iyz>
            <izz>1</izz>
          </inertia>
        </inertial>
        <collision name='wheel1_link_collision'>
          <pose frame=''>0 0 0 0 -0 0</pose>
          <geometry>
            <cylinder>
              <length>0.16</length>
              <radius>0.2</radius>
            </cylinder>
          </geometry>
          <surface>
            <contact>
              <ode/>
            </contact>
            <friction>
              <ode/>
              <torsional>
                <ode/>
              </torsional>
            </friction>
            <bounce/>
          </surface>
          <max_contacts>10</max_contacts>
        </collision>
        <visual name='wheel1_link_visual'>
          <pose frame=''>0 0 0 0 -0 0</pose>
          <geometry>
            <cylinder>
              <length>0.16</length>
              <radius>0.2</radius>
            </cylinder>
          </geometry>
          <material>
            <script>
              <name>Gazebo/Black</name>
              <uri>file://media/materials/scripts/gazebo.material</uri>
            </script>
          </material>
        </visual>
        <gravity>1</gravity>
        <velocity_decay/>
        <self_collide>0</self_collide>
        <kinematic>0</kinematic>
      </link>
      <joint name='wheel1' type='revolute'>
        <child>wheel1_link</child>
        <parent>leg1</parent>
        <axis>
          <xyz>0 1 0</xyz>
          <limit>
            <lower>-1e+16</lower>
            <upper>1e+16</upper>
          </limit>
          <dynamics>
            <spring_reference>0</spring_reference>
            <spring_stiffness>0</spring_stiffness>
          </dynamics>
          <use_parent_model_frame>1</use_parent_model_frame>
        </axis>
      </joint>
      <link name='leg2'>
        <pose frame=''>0.547 0.3 0.2 0 -0 0</pose>
        <inertial>
          <pose frame=''>0 0 0 0 -0 0</pose>
          <mass>1</mass>
          <inertia>
            <ixx>1</ixx>
            <ixy>0</ixy>
            <ixz>0</ixz>
            <iyy>1</iyy>
            <iyz>0</iyz>
            <izz>1</izz>
          </inertia>
        </inertial>
        <collision name='leg2_collision'>
          <pose frame=''>0 0 0 0 -0 0</pose>
          <geometry>
            <mesh>
              <scale>1 1 1</scale>
              <uri>/home/vigneshnuc/Thorvald/src/Thorvald/thorvald_model/meshes/drive_modules/836745-5-DUMMY-RevA.stl</uri>
            </mesh>
          </geometry>
          <max_contacts>10</max_contacts>
          <surface>
            <contact>
              <ode/>
            </contact>
            <bounce/>
            <friction>
              <torsional>
                <ode/>
              </torsional>
              <ode/>
            </friction>
          </surface>
        </collision>
        <visual name='leg2_visual'>
          <pose frame=''>0 0 0 0 -0 0</pose>
          <geometry>
            <mesh>
              <scale>1 1 1</scale>
              <uri>/home/vigneshnuc/Thorvald/src/Thorvald/thorvald_model/meshes/drive_modules/836745-5-DUMMY-RevA.stl</uri>
            </mesh>
          </geometry>
        </visual>
        <self_collide>0</self_collide>
        <kinematic>0</kinematic>
      </link>
      <joint name='steering2' type='revolute'>
        <child>leg2</child>
        <parent>base_link</parent>
        <axis>
          <xyz>0 0 1</xyz>
          <limit>
            <lower>-1e+16</lower>
            <upper>1e+16</upper>
          </limit>
          <dynamics>
            <spring_reference>0</spring_reference>
            <spring_stiffness>0</spring_stiffness>
          </dynamics>
          <use_parent_model_frame>1</use_parent_model_frame>
        </axis>
      </joint>
      <link name='wheel2_link'>
        <pose frame=''>0.547 0.3 0.2 -1.5708 0 0</pose>
        <inertial>
          <pose frame=''>0 0 0 0 -0 0</pose>
          <mass>1</mass>
          <inertia>
            <ixx>1</ixx>
            <ixy>0</ixy>
            <ixz>0</ixz>
            <iyy>1</iyy>
            <iyz>0</iyz>
            <izz>1</izz>
          </inertia>
        </inertial>
        <collision name='wheel2_link_collision'>
          <pose frame=''>0 0 0 0 -0 0</pose>
          <geometry>
            <cylinder>
              <length>0.16</length>
              <radius>0.2</radius>
            </cylinder>
          </geometry>
          <surface>
            <contact>
              <ode/>
            </contact>
            <friction>
              <ode/>
              <torsional>
                <ode/>
              </torsional>
            </friction>
            <bounce/>
          </surface>
          <max_contacts>10</max_contacts>
        </collision>
        <visual name='wheel2_link_visual'>
          <pose frame=''>0 0 0 0 -0 0</pose>
          <geometry>
            <cylinder>
              <length>0.16</length>
              <radius>0.2</radius>
            </cylinder>
          </geometry>
          <material>
            <script>
              <name>Gazebo/Black</name>
              <uri>file://media/materials/scripts/gazebo.material</uri>
            </script>
          </material>
        </visual>
        <gravity>1</gravity>
        <velocity_decay/>
        <self_collide>0</self_collide>
        <kinematic>0</kinematic>
      </link>
      <joint name='wheel2' type='revolute'>
        <child>wheel2_link</child>
        <parent>leg2</parent>
        <axis>
          <xyz>0 1 0</xyz>
          <limit>
            <lower>-1e+16</lower>
            <upper>1e+16</upper>
          </limit>
          <dynamics>
            <spring_reference>0</spring_reference>
            <spring_stiffness>0</spring_stiffness>
          </dynamics>
          <use_parent_model_frame>1</use_parent_model_frame>
        </axis>
      </joint>
      <link name='leg3'>
        <pose frame=''>-0.547 0.3 0.2 0 -0 0</pose>
        <inertial>
          <pose frame=''>0 0 0 0 -0 0</pose>
          <mass>1</mass>
          <inertia>
            <ixx>1</ixx>
            <ixy>0</ixy>
            <ixz>0</ixz>
            <iyy>1</iyy>
            <iyz>0</iyz>
            <izz>1</izz>
          </inertia>
        </inertial>
        <collision name='leg3_collision'>
          <pose frame=''>0 0 0 0 -0 -3.14159</pose>
          <geometry>
            <mesh>
              <scale>1 1 1</scale>
              <uri>/home/vigneshnuc/Thorvald/src/Thorvald/thorvald_model/meshes/drive_modules/836745-5-DUMMY-MIRROR-RevA.stl</uri>
            </mesh>
          </geometry>
          <max_contacts>10</max_contacts>
          <surface>
            <contact>
              <ode/>
            </contact>
            <bounce/>
            <friction>
              <torsional>
                <ode/>
              </torsional>
              <ode/>
            </friction>
          </surface>
        </collision>
        <visual name='leg3_visual'>
          <pose frame=''>0 0 0 0 -0 -3.14159</pose>
          <geometry>
            <mesh>
              <scale>1 1 1</scale>
              <uri>/home/vigneshnuc/Thorvald/src/Thorvald/thorvald_model/meshes/drive_modules/836745-5-DUMMY-MIRROR-RevA.stl</uri>
            </mesh>
          </geometry>
        </visual>
        <self_collide>0</self_collide>
        <kinematic>0</kinematic>
      </link>
      <joint name='steering3' type='revolute'>
        <child>leg3</child>
        <parent>base_link</parent>
        <axis>
          <xyz>0 0 1</xyz>
          <limit>
            <lower>-1e+16</lower>
            <upper>1e+16</upper>
          </limit>
          <dynamics>
            <spring_reference>0</spring_reference>
            <spring_stiffness>0</spring_stiffness>
          </dynamics>
          <use_parent_model_frame>1</use_parent_model_frame>
        </axis>
      </joint>
      <link name='wheel3_link'>
        <pose frame=''>-0.547 0.3 0.2 -1.5708 0 0</pose>
        <inertial>
          <pose frame=''>0 0 0 0 -0 0</pose>
          <mass>1</mass>
          <inertia>
            <ixx>1</ixx>
            <ixy>0</ixy>
            <ixz>0</ixz>
            <iyy>1</iyy>
            <iyz>0</iyz>
            <izz>1</izz>
          </inertia>
        </inertial>
        <collision name='wheel3_link_collision'>
          <pose frame=''>0 0 0 0 -0 0</pose>
          <geometry>
            <cylinder>
              <length>0.16</length>
              <radius>0.2</radius>
            </cylinder>
          </geometry>
          <surface>
            <contact>
              <ode/>
            </contact>
            <friction>
              <ode/>
              <torsional>
                <ode/>
              </torsional>
            </friction>
            <bounce/>
          </surface>
          <max_contacts>10</max_contacts>
        </collision>
        <visual name='wheel3_link_visual'>
          <pose frame=''>0 0 0 0 -0 0</pose>
          <geometry>
            <cylinder>
              <length>0.16</length>
              <radius>0.2</radius>
            </cylinder>
          </geometry>
          <material>
            <script>
              <name>Gazebo/Black</name>
              <uri>file://media/materials/scripts/gazebo.material</uri>
            </script>
          </material>
        </visual>
        <gravity>1</gravity>
        <velocity_decay/>
        <self_collide>0</self_collide>
        <kinematic>0</kinematic>
      </link>
      <joint name='wheel3' type='revolute'>
        <child>wheel3_link</child>
        <parent>leg3</parent>
        <axis>
          <xyz>0 1 0</xyz>
          <limit>
            <lower>-1e+16</lower>
            <upper>1e+16</upper>
          </limit>
          <dynamics>
            <spring_reference>0</spring_reference>
            <spring_stiffness>0</spring_stiffness>
          </dynamics>
          <use_parent_model_frame>1</use_parent_model_frame>
        </axis>
      </joint>
      <static>0</static>
      <plugin name='thorvald_gazebo_plugins' filename='libthorvald_gazebo_plugins.so'>
        <alwaysOn>true</alwaysOn>
        <robotNamespace>thorvald_ii</robotNamespace>
        <updateRate>20</updateRate>
        <steering0>steering0</steering0>
        <steering1>steering1</steering1>
        <steering2>steering2</steering2>
        <steering3>steering3</steering3>
        <wheel0>wheel0</wheel0>
        <wheel1>wheel1</wheel1>
        <wheel2>wheel2</wheel2>
        <wheel3>wheel3</wheel3>
        <commandTopic>base_state</commandTopic>
        <odometryTopic>odom</odometryTopic>
        <odometryFrame>odom</odometryFrame>
        <robotBaseFrame>base_link</robotBaseFrame>
      </plugin>
      <pose frame=''>0 0 0 0 -0 0</pose>
    </model>
    <model name='pole'>
      <link name='link_0'>
        <pose frame=''>0 0 0 0 -0 0</pose>
        <inertial>
          <mass>0.0364582</mass>
          <inertia>
            <ixx>0.00312124</ixx>
            <ixy>0</ixy>
            <ixz>0</ixz>
            <iyy>0.00312124</iyy>
            <iyz>0</iyz>
            <izz>0.00016615</izz>
          </inertia>
          <pose frame=''>0 0 0 0 -0 0</pose>
        </inertial>
        <gravity>1</gravity>
        <self_collide>0</self_collide>
        <kinematic>0</kinematic>
        <visual name='visual'>
          <pose frame=''>0 0 0 0 -0 0</pose>
          <geometry>
            <cylinder>
              <radius>0.06</radius>
              <length>2.5</length>
            </cylinder>
          </geometry>
          <material>
            <lighting>1</lighting>
            <script>
              <uri>file://media/materials/scripts/gazebo.material</uri>
              <name>Gazebo/Grey</name>
            </script>
            <ambient>0.3 0.3 0.3 1</ambient>
            <diffuse>0.7 0.7 0.7 1</diffuse>
            <specular>0.01 0.01 0.01 1</specular>
            <emissive>0 0 0 1</emissive>
            <shader type='vertex'>
              <normal_map>__default__</normal_map>
            </shader>
          </material>
          <cast_shadows>1</cast_shadows>
          <transparency>0</transparency>
        </visual>
        <collision name='collision'>
          <laser_retro>0</laser_retro>
          <max_contacts>10</max_contacts>
          <pose frame=''>0 0 0 0 -0 0</pose>
          <geometry>
            <cylinder>
              <radius>0.06</radius>
              <length>2.5</length>
            </cylinder>
          </geometry>
          <surface>
            <friction>
              <ode>
                <mu>1</mu>
                <mu2>1</mu2>
                <fdir1>0 0 0</fdir1>
                <slip1>0</slip1>
                <slip2>0</slip2>
              </ode>
              <torsional>
                <coefficient>1</coefficient>
                <patch_radius>0</patch_radius>
                <surface_radius>0</surface_radius>
                <use_patch_radius>1</use_patch_radius>
                <ode>
                  <slip>0</slip>
                </ode>
              </torsional>
            </friction>
            <bounce>
              <restitution_coefficient>0</restitution_coefficient>
              <threshold>1e+06</threshold>
            </bounce>
            <contact>
              <collide_without_contact>0</collide_without_contact>
              <collide_without_contact_bitmask>1</collide_without_contact_bitmask>
              <collide_bitmask>1</collide_bitmask>
              <ode>
                <soft_cfm>0</soft_cfm>
                <soft_erp>0.2</soft_erp>
                <kp>1e+13</kp>
                <kd>1</kd>
                <max_vel>0.01</max_vel>
                <min_depth>0</min_depth>
              </ode>
              <bullet>
                <split_impulse>1</split_impulse>
                <split_impulse_penetration_threshold>-0.01</split_impulse_penetration_threshold>
                <soft_cfm>0</soft_cfm>
                <soft_erp>0.2</soft_erp>
                <kp>1e+13</kp>
                <kd>1</kd>
              </bullet>
            </contact>
          </surface>
        </collision>
      </link>
      <static>0</static>
      <allow_auto_disable>1</allow_auto_disable>
      <pose frame=''>2.09535 0.925526 0 0 -0 0</pose>
    </model>
    <model name='pole_0'>
      <link name='link_0'>
        <pose frame=''>0 0 0 0 -0 0</pose>
        <inertial>
          <mass>0.0364582</mass>
          <inertia>
            <ixx>0.00312124</ixx>
            <ixy>0</ixy>
            <ixz>0</ixz>
            <iyy>0.00312124</iyy>
            <iyz>0</iyz>
            <izz>0.00016615</izz>
          </inertia>
          <pose frame=''>0 0 0 0 -0 0</pose>
        </inertial>
        <gravity>1</gravity>
        <self_collide>0</self_collide>
        <kinematic>0</kinematic>
        <visual name='visual'>
          <pose frame=''>0 0 0 0 -0 0</pose>
          <geometry>
            <cylinder>
              <radius>0.06</radius>
              <length>2.5</length>
            </cylinder>
          </geometry>
          <material>
            <lighting>1</lighting>
            <script>
              <uri>file://media/materials/scripts/gazebo.material</uri>
              <name>Gazebo/Grey</name>
            </script>
            <ambient>0.3 0.3 0.3 1</ambient>
            <diffuse>0.7 0.7 0.7 1</diffuse>
            <specular>0.01 0.01 0.01 1</specular>
            <emissive>0 0 0 1</emissive>
            <shader type='vertex'>
              <normal_map>__default__</normal_map>
            </shader>
          </material>
          <cast_shadows>1</cast_shadows>
          <transparency>0</transparency>
        </visual>
        <collision name='collision'>
          <laser_retro>0</laser_retro>
          <max_contacts>10</max_contacts>
          <pose frame=''>0 0 0 0 -0 0</pose>
          <geometry>
            <cylinder>
              <radius>0.06</radius>
              <length>2.5</length>
            </cylinder>
          </geometry>
          <surface>
            <friction>
              <ode>
                <mu>1</mu>
                <mu2>1</mu2>
                <fdir1>0 0 0</fdir1>
                <slip1>0</slip1>
                <slip2>0</slip2>
              </ode>
              <torsional>
                <coefficient>1</coefficient>
                <patch_radius>0</patch_radius>
                <surface_radius>0</surface_radius>
                <use_patch_radius>1</use_patch_radius>
                <ode>
                  <slip>0</slip>
                </ode>
              </torsional>
            </friction>
            <bounce>
              <restitution_coefficient>0</restitution_coefficient>
              <threshold>1e+06</threshold>
            </bounce>
            <contact>
              <collide_without_contact>0</collide_without_contact>
              <collide_without_contact_bitmask>1</collide_without_contact_bitmask>
              <collide_bitmask>1</collide_bitmask>
              <ode>
                <soft_cfm>0</soft_cfm>
                <soft_erp>0.2</soft_erp>
                <kp>1e+13</kp>
                <kd>1</kd>
                <max_vel>0.01</max_vel>
                <min_depth>0</min_depth>
              </ode>
              <bullet>
                <split_impulse>1</split_impulse>
                <split_impulse_penetration_threshold>-0.01</split_impulse_penetration_threshold>
                <soft_cfm>0</soft_cfm>
                <soft_erp>0.2</soft_erp>
                <kp>1e+13</kp>
                <kd>1</kd>
              </bullet>
            </contact>
          </surface>
        </collision>
      </link>
      <static>0</static>
      <allow_auto_disable>1</allow_auto_disable>
      <pose frame=''>1.82758 2.01655 0 0 -0 0</pose>
    </model>
    <model name='pole_1'>
      <link name='link_0'>
        <pose frame=''>0 0 0 0 -0 0</pose>
        <inertial>
          <mass>0.0364582</mass>
          <inertia>
            <ixx>0.00312124</ixx>
            <ixy>0</ixy>
            <ixz>0</ixz>
            <iyy>0.00312124</iyy>
            <iyz>0</iyz>
            <izz>0.00016615</izz>
          </inertia>
          <pose frame=''>0 0 0 0 -0 0</pose>
        </inertial>
        <gravity>1</gravity>
        <self_collide>0</self_collide>
        <kinematic>0</kinematic>
        <visual name='visual'>
          <pose frame=''>0 0 0 0 -0 0</pose>
          <geometry>
            <cylinder>
              <radius>0.06</radius>
              <length>2.5</length>
            </cylinder>
          </geometry>
          <material>
            <lighting>1</lighting>
            <script>
              <uri>file://media/materials/scripts/gazebo.material</uri>
              <name>Gazebo/Grey</name>
            </script>
            <ambient>0.3 0.3 0.3 1</ambient>
            <diffuse>0.7 0.7 0.7 1</diffuse>
            <specular>0.01 0.01 0.01 1</specular>
            <emissive>0 0 0 1</emissive>
            <shader type='vertex'>
              <normal_map>__default__</normal_map>
            </shader>
          </material>
          <cast_shadows>1</cast_shadows>
          <transparency>0</transparency>
        </visual>
        <collision name='collision'>
          <laser_retro>0</laser_retro>
          <max_contacts>10</max_contacts>
          <pose frame=''>0 0 0 0 -0 0</pose>
          <geometry>
            <cylinder>
              <radius>0.06</radius>
              <length>2.5</length>
            </cylinder>
          </geometry>
          <surface>
            <friction>
              <ode>
                <mu>1</mu>
                <mu2>1</mu2>
                <fdir1>0 0 0</fdir1>
                <slip1>0</slip1>
                <slip2>0</slip2>
              </ode>
              <torsional>
                <coefficient>1</coefficient>
                <patch_radius>0</patch_radius>
                <surface_radius>0</surface_radius>
                <use_patch_radius>1</use_patch_radius>
                <ode>
                  <slip>0</slip>
                </ode>
              </torsional>
            </friction>
            <bounce>
              <restitution_coefficient>0</restitution_coefficient>
              <threshold>1e+06</threshold>
            </bounce>
            <contact>
              <collide_without_contact>0</collide_without_contact>
              <collide_without_contact_bitmask>1</collide_without_contact_bitmask>
              <collide_bitmask>1</collide_bitmask>
              <ode>
                <soft_cfm>0</soft_cfm>
                <soft_erp>0.2</soft_erp>
                <kp>1e+13</kp>
                <kd>1</kd>
                <max_vel>0.01</max_vel>
                <min_depth>0</min_depth>
              </ode>
              <bullet>
                <split_impulse>1</split_impulse>
                <split_impulse_penetration_threshold>-0.01</split_impulse_penetration_threshold>
                <soft_cfm>0</soft_cfm>
                <soft_erp>0.2</soft_erp>
                <kp>1e+13</kp>
                <kd>1</kd>
              </bullet>
            </contact>
          </surface>
        </collision>
      </link>
      <static>0</static>
      <allow_auto_disable>1</allow_auto_disable>
      <pose frame=''>2.30052 -1.25535 0 0 -0 0</pose>
    </model>
    <model name='pole_2'>
      <link name='link_0'>
        <pose frame=''>0 0 0 0 -0 0</pose>
        <inertial>
          <mass>0.0364582</mass>
          <inertia>
            <ixx>0.00312124</ixx>
            <ixy>0</ixy>
            <ixz>0</ixz>
            <iyy>0.00312124</iyy>
            <iyz>0</iyz>
            <izz>0.00016615</izz>
          </inertia>
          <pose frame=''>0 0 0 0 -0 0</pose>
        </inertial>
        <gravity>1</gravity>
        <self_collide>0</self_collide>
        <kinematic>0</kinematic>
        <visual name='visual'>
          <pose frame=''>0 0 0 0 -0 0</pose>
          <geometry>
            <cylinder>
              <radius>0.06</radius>
              <length>2.5</length>
            </cylinder>
          </geometry>
          <material>
            <lighting>1</lighting>
            <script>
              <uri>file://media/materials/scripts/gazebo.material</uri>
              <name>Gazebo/Grey</name>
            </script>
            <ambient>0.3 0.3 0.3 1</ambient>
            <diffuse>0.7 0.7 0.7 1</diffuse>
            <specular>0.01 0.01 0.01 1</specular>
            <emissive>0 0 0 1</emissive>
            <shader type='vertex'>
              <normal_map>__default__</normal_map>
            </shader>
          </material>
          <cast_shadows>1</cast_shadows>
          <transparency>0</transparency>
        </visual>
        <collision name='collision'>
          <laser_retro>0</laser_retro>
          <max_contacts>10</max_contacts>
          <pose frame=''>0 0 0 0 -0 0</pose>
          <geometry>
            <cylinder>
              <radius>0.06</radius>
              <length>2.5</length>
            </cylinder>
          </geometry>
          <surface>
            <friction>
              <ode>
                <mu>1</mu>
                <mu2>1</mu2>
                <fdir1>0 0 0</fdir1>
                <slip1>0</slip1>
                <slip2>0</slip2>
              </ode>
              <torsional>
                <coefficient>1</coefficient>
                <patch_radius>0</patch_radius>
                <surface_radius>0</surface_radius>
                <use_patch_radius>1</use_patch_radius>
                <ode>
                  <slip>0</slip>
                </ode>
              </torsional>
            </friction>
            <bounce>
              <restitution_coefficient>0</restitution_coefficient>
              <threshold>1e+06</threshold>
            </bounce>
            <contact>
              <collide_without_contact>0</collide_without_contact>
              <collide_without_contact_bitmask>1</collide_without_contact_bitmask>
              <collide_bitmask>1</collide_bitmask>
              <ode>
                <soft_cfm>0</soft_cfm>
                <soft_erp>0.2</soft_erp>
                <kp>1e+13</kp>
                <kd>1</kd>
                <max_vel>0.01</max_vel>
                <min_depth>0</min_depth>
              </ode>
              <bullet>
                <split_impulse>1</split_impulse>
                <split_impulse_penetration_threshold>-0.01</split_impulse_penetration_threshold>
                <soft_cfm>0</soft_cfm>
                <soft_erp>0.2</soft_erp>
                <kp>1e+13</kp>
                <kd>1</kd>
              </bullet>
            </contact>
          </surface>
        </collision>
      </link>
      <static>0</static>
      <allow_auto_disable>1</allow_auto_disable>
      <pose frame=''>2.50986 -3.3904 0 0 -0 0</pose>
    </model>
    <model name='pole_3'>
      <link name='link_0'>
        <pose frame=''>0 0 0 0 -0 0</pose>
        <inertial>
          <mass>0.0364582</mass>
          <inertia>
            <ixx>0.00312124</ixx>
            <ixy>0</ixy>
            <ixz>0</ixz>
            <iyy>0.00312124</iyy>
            <iyz>0</iyz>
            <izz>0.00016615</izz>
          </inertia>
          <pose frame=''>0 0 0 0 -0 0</pose>
        </inertial>
        <gravity>1</gravity>
        <self_collide>0</self_collide>
        <kinematic>0</kinematic>
        <visual name='visual'>
          <pose frame=''>0 0 0 0 -0 0</pose>
          <geometry>
            <cylinder>
              <radius>0.06</radius>
              <length>2.5</length>
            </cylinder>
          </geometry>
          <material>
            <lighting>1</lighting>
            <script>
              <uri>file://media/materials/scripts/gazebo.material</uri>
              <name>Gazebo/Grey</name>
            </script>
            <ambient>0.3 0.3 0.3 1</ambient>
            <diffuse>0.7 0.7 0.7 1</diffuse>
            <specular>0.01 0.01 0.01 1</specular>
            <emissive>0 0 0 1</emissive>
            <shader type='vertex'>
              <normal_map>__default__</normal_map>
            </shader>
          </material>
          <cast_shadows>1</cast_shadows>
          <transparency>0</transparency>
        </visual>
        <collision name='collision'>
          <laser_retro>0</laser_retro>
          <max_contacts>10</max_contacts>
          <pose frame=''>0 0 0 0 -0 0</pose>
          <geometry>
            <cylinder>
              <radius>0.06</radius>
              <length>2.5</length>
            </cylinder>
          </geometry>
          <surface>
            <friction>
              <ode>
                <mu>1</mu>
                <mu2>1</mu2>
                <fdir1>0 0 0</fdir1>
                <slip1>0</slip1>
                <slip2>0</slip2>
              </ode>
              <torsional>
                <coefficient>1</coefficient>
                <patch_radius>0</patch_radius>
                <surface_radius>0</surface_radius>
                <use_patch_radius>1</use_patch_radius>
                <ode>
                  <slip>0</slip>
                </ode>
              </torsional>
            </friction>
            <bounce>
              <restitution_coefficient>0</restitution_coefficient>
              <threshold>1e+06</threshold>
            </bounce>
            <contact>
              <collide_without_contact>0</collide_without_contact>
              <collide_without_contact_bitmask>1</collide_without_contact_bitmask>
              <collide_bitmask>1</collide_bitmask>
              <ode>
                <soft_cfm>0</soft_cfm>
                <soft_erp>0.2</soft_erp>
                <kp>1e+13</kp>
                <kd>1</kd>
                <max_vel>0.01</max_vel>
                <min_depth>0</min_depth>
              </ode>
              <bullet>
                <split_impulse>1</split_impulse>
                <split_impulse_penetration_threshold>-0.01</split_impulse_penetration_threshold>
                <soft_cfm>0</soft_cfm>
                <soft_erp>0.2</soft_erp>
                <kp>1e+13</kp>
                <kd>1</kd>
              </bullet>
            </contact>
          </surface>
        </collision>
      </link>
      <static>0</static>
      <allow_auto_disable>1</allow_auto_disable>
      <pose frame=''>2.38554 3.37215 0 0 -0 0</pose>
    </model>
    <model name='pole_4'>
      <link name='link_0'>
        <pose frame=''>0 0 0 0 -0 0</pose>
        <inertial>
          <mass>0.0364582</mass>
          <inertia>
            <ixx>0.00312124</ixx>
            <ixy>0</ixy>
            <ixz>0</ixz>
            <iyy>0.00312124</iyy>
            <iyz>0</iyz>
            <izz>0.00016615</izz>
          </inertia>
          <pose frame=''>0 0 0 0 -0 0</pose>
        </inertial>
        <gravity>1</gravity>
        <self_collide>0</self_collide>
        <kinematic>0</kinematic>
        <visual name='visual'>
          <pose frame=''>0 0 0 0 -0 0</pose>
          <geometry>
            <cylinder>
              <radius>0.06</radius>
              <length>2.5</length>
            </cylinder>
          </geometry>
          <material>
            <lighting>1</lighting>
            <script>
              <uri>file://media/materials/scripts/gazebo.material</uri>
              <name>Gazebo/Grey</name>
            </script>
            <ambient>0.3 0.3 0.3 1</ambient>
            <diffuse>0.7 0.7 0.7 1</diffuse>
            <specular>0.01 0.01 0.01 1</specular>
            <emissive>0 0 0 1</emissive>
            <shader type='vertex'>
              <normal_map>__default__</normal_map>
            </shader>
          </material>
          <cast_shadows>1</cast_shadows>
          <transparency>0</transparency>
        </visual>
        <collision name='collision'>
          <laser_retro>0</laser_retro>
          <max_contacts>10</max_contacts>
          <pose frame=''>0 0 0 0 -0 0</pose>
          <geometry>
            <cylinder>
              <radius>0.06</radius>
              <length>2.5</length>
            </cylinder>
          </geometry>
          <surface>
            <friction>
              <ode>
                <mu>1</mu>
                <mu2>1</mu2>
                <fdir1>0 0 0</fdir1>
                <slip1>0</slip1>
                <slip2>0</slip2>
              </ode>
              <torsional>
                <coefficient>1</coefficient>
                <patch_radius>0</patch_radius>
                <surface_radius>0</surface_radius>
                <use_patch_radius>1</use_patch_radius>
                <ode>
                  <slip>0</slip>
                </ode>
              </torsional>
            </friction>
            <bounce>
              <restitution_coefficient>0</restitution_coefficient>
              <threshold>1e+06</threshold>
            </bounce>
            <contact>
              <collide_without_contact>0</collide_without_contact>
              <collide_without_contact_bitmask>1</collide_without_contact_bitmask>
              <collide_bitmask>1</collide_bitmask>
              <ode>
                <soft_cfm>0</soft_cfm>
                <soft_erp>0.2</soft_erp>
                <kp>1e+13</kp>
                <kd>1</kd>
                <max_vel>0.01</max_vel>
                <min_depth>0</min_depth>
              </ode>
              <bullet>
                <split_impulse>1</split_impulse>
                <split_impulse_penetration_threshold>-0.01</split_impulse_penetration_threshold>
                <soft_cfm>0</soft_cfm>
                <soft_erp>0.2</soft_erp>
                <kp>1e+13</kp>
                <kd>1</kd>
              </bullet>
            </contact>
          </surface>
        </collision>
      </link>
      <static>0</static>
      <allow_auto_disable>1</allow_auto_disable>
      <pose frame=''>2.5868 -4.32499 0 0 -0 0</pose>
    </model>
    <state world_name='default'>
      <sim_time>221 680000000</sim_time>
      <real_time>228 626398649</real_time>
      <wall_time>1521111550 246629125</wall_time>
      <iterations>221680</iterations>
      <model name='ground_plane'>
        <pose frame=''>0 0 0 0 -0 0</pose>
        <scale>1 1 1</scale>
        <link name='link'>
          <pose frame=''>0 0 0 0 -0 0</pose>
          <velocity>0 0 0 0 -0 0</velocity>
          <acceleration>0 0 0 0 -0 0</acceleration>
          <wrench>0 0 0 0 -0 0</wrench>
        </link>
      </model>
      <model name='pole'>
        <pose frame=''>1.39234 0.701065 1.24999 -1.4e-05 -0.000313 0.045758</pose>
        <scale>1 1 1</scale>
        <link name='link_0'>
          <pose frame=''>1.39234 0.701065 1.24999 -1.4e-05 -0.000313 0.045758</pose>
          <velocity>0 0 0 0 -0 0</velocity>
          <acceleration>0 0 -9.8 0 -0 0</acceleration>
          <wrench>0 0 -0.35729 0 -0 0</wrench>
        </link>
      </model>
      <model name='pole_0'>
        <pose frame=''>1.40002 2.10014 1.24999 -1e-06 -0 -0.002151</pose>
        <scale>1 1 1</scale>
        <link name='link_0'>
          <pose frame=''>1.40002 2.10014 1.24999 -1e-06 -0 -0.002151</pose>
          <velocity>0 0 0 0 -0 0</velocity>
          <acceleration>0 0 -9.8 0 -0 0</acceleration>
          <wrench>0 0 -0.35729 0 -0 0</wrench>
        </link>
      </model>
      <model name='pole_1'>
        <pose frame=''>1.40002 -0.699873 1.25 -1e-06 1e-06 -0.002604</pose>
        <scale>1 1 1</scale>
        <link name='link_0'>
          <pose frame=''>1.40002 -0.699873 1.25 -1e-06 1e-06 -0.002604</pose>
          <velocity>0 0 0 0 -0 0</velocity>
          <acceleration>0 0 -9.8 0 -0 0</acceleration>
          <wrench>0 0 -0.35729 0 -0 0</wrench>
        </link>
      </model>
      <model name='pole_2'>
        <pose frame=''>1.40001 -2.09995 1.25 -0 2e-06 -0.001738</pose>
        <scale>1 1 1</scale>
        <link name='link_0'>
          <pose frame=''>1.40001 -2.09995 1.25 -0 2e-06 -0.001738</pose>
          <velocity>0 0 0 0 -0 0</velocity>
          <acceleration>0 0 -9.8 0 -0 0</acceleration>
          <wrench>0 0 -0.35729 0 -0 0</wrench>
        </link>
      </model>
      <model name='pole_3'>
        <pose frame=''>1.40003 3.50017 1.25 -1e-06 -0 -0.000459</pose>
        <scale>1 1 1</scale>
        <link name='link_0'>
          <pose frame=''>1.40003 3.50017 1.25 -1e-06 -0 -0.000459</pose>
          <velocity>0 0 0 0 -0 0</velocity>
          <acceleration>0 0 -9.8 0 -0 0</acceleration>
          <wrench>0 0 -0.35729 0 -0 0</wrench>
        </link>
      </model>
      <model name='pole_4'>
        <pose frame=''>1.4 -3.49997 1.25 -1e-06 1e-06 0.000363</pose>
        <scale>1 1 1</scale>
        <link name='link_0'>
          <pose frame=''>1.4 -3.49997 1.25 -1e-06 1e-06 0.000363</pose>
          <velocity>0 0 0 0 -0 0</velocity>
          <acceleration>0 0 -9.8 0 -0 0</acceleration>
          <wrench>0 0 -0.35729 0 -0 0</wrench>
        </link>
      </model>
      <model name='thorvald_ii'>
        <pose frame=''>0.003728 0.037512 -1.5e-05 -1.4e-05 -0 -0.003015</pose>
        <scale>1 1 1</scale>
        <link name='base_link'>
          <pose frame=''>0.003728 0.037512 -1.5e-05 -1.4e-05 -0 -0.003015</pose>
          <velocity>3.6e-05 0.000182 -0.004759 3.5e-05 -3.8e-05 -1.4e-05</velocity>
          <acceleration>-0.00343 -0.023885 -9.51873 0.069722 -0.075984 -0.000322</acceleration>
          <wrench>-0.288105 -2.00633 -799.573 0 -0 0</wrench>
        </link>
        <link name='leg0'>
          <pose frame=''>-0.544174 -0.260835 0.199993 -1.3e-05 0 -0.003014</pose>
          <velocity>1.7e-05 0.000262 -0.005722 -0.00012 -3.7e-05 3e-06</velocity>
          <acceleration>0.006893 0.158527 -11.4436 -0.239052 -0.074536 -0.000119</acceleration>
          <wrench>0.006893 0.158527 -11.4436 0 -0 0</wrench>
        </link>
        <link name='leg1'>
          <pose frame=''>0.549821 -0.264133 0.199993 -1.3e-05 0 -0.003014</pose>
          <velocity>2.8e-05 0.00024 -0.005713 -0.000122 -1.6e-05 2.2e-05</velocity>
          <acceleration>0.02847 0.143815 -11.4272 -0.243415 -0.032902 -0.000548</acceleration>
          <wrench>0.02847 0.143815 -11.4272 0 -0 0</wrench>
        </link>
        <link name='leg2'>
          <pose frame=''>0.55163 0.335864 0.199989 -1.4e-05 -0 -0.003013</pose>
          <velocity>5.4e-05 0.000228 -0.006648 -6e-06 -3.8e-05 6.7e-05</velocity>
          <acceleration>0.064338 0.12118 -13.2962 -0.010766 -0.076808 -0.001742</acceleration>
          <wrench>0.064338 0.12118 -13.2962 0 -0 0</wrench>
        </link>
        <link name='leg3'>
          <pose frame=''>-0.542365 0.339163 0.199979 -1.4e-05 -0 -0.003014</pose>
          <velocity>3.2e-05 0.000169 -0.004152 4.2e-05 -8.3e-05 2.2e-05</velocity>
          <acceleration>0.019812 -0.02805 -8.30502 0.083394 -0.16547 -0.000561</acceleration>
          <wrench>0.019812 -0.02805 -8.30502 0 -0 0</wrench>
        </link>
        <link name='wheel0_link'>
          <pose frame=''>-0.544174 -0.260836 0.199996 -1.57081 0.012103 -0.003015</pose>
          <velocity>1.6e-05 0.000415 -0.006372 -0.000241 5.8e-05 3e-06</velocity>
          <acceleration>0.00459 0.462583 -12.745 -0.481379 0.001451 0.000121</acceleration>
          <wrench>0.00459 0.462583 -12.745 0 -0 0</wrench>
        </link>
        <link name='wheel1_link'>
          <pose frame=''>0.549821 -0.264134 0.199996 -1.57081 -0.006603 -0.003014</pose>
          <velocity>3.4e-05 0.000384 -0.006391 -0.000241 -3.1e-05 2.3e-05</velocity>
          <acceleration>0.040529 0.431833 -12.782 -0.480849 0.001449 0.000549</acceleration>
          <wrench>0.040529 0.431833 -12.782 0 -0 0</wrench>
        </link>
        <link name='wheel2_link'>
          <pose frame=''>0.55163 0.335864 0.199994 -1.57081 -0.021969 -0.003013</pose>
          <velocity>6.6e-05 0.000344 -0.008014 -4.2e-05 -0.000104 6.8e-05</velocity>
          <acceleration>0.087536 0.352226 -16.0283 -0.083401 0.000251 0.001743</acceleration>
          <wrench>0.087536 0.352226 -16.0283 0 -0 0</wrench>
        </link>
        <link name='wheel3_link'>
          <pose frame=''>-0.542365 0.339162 0.199994 -1.57081 0.004588 -0.003014</pose>
          <velocity>4e-05 0.000365 -0.008 5e-06 2.2e-05 2.2e-05</velocity>
          <acceleration>0.035936 0.364216 -15.9993 0.010156 -3.1e-05 0.000563</acceleration>
          <wrench>0.035936 0.364216 -15.9993 0 -0 0</wrench>
        </link>
      </model>
      <light name='sun'>
        <pose frame=''>0 0 10 0 -0 0</pose>
      </light>
    </state>
    <gui fullscreen='0'>
      <camera name='user_camera'>
        <pose frame=''>-10.9915 -1.57526 7.8868 0 0.342073 0.272211</pose>
        <view_controller>orbit</view_controller>
        <projection_type>perspective</projection_type>
      </camera>
    </gui>
  </world>
</sdf>
